Traceback (most recent call last):
  File "E:\Program Files\Python313\Lib\site-packages\jupyter_cache\executors\utils.py", line 58, in single_nb_execution
    executenb(
    ~~~~~~~~~^
        nb,
        ^^^
    ...<4 lines>...
        **kwargs,
        ^^^^^^^^^
    )
    ^
  File "E:\Program Files\Python313\Lib\site-packages\nbclient\client.py", line 1314, in execute
    return NotebookClient(nb=nb, resources=resources, km=km, **kwargs).execute()
           ~~~~~~~~~~~~~~~~~~~~~~~~~~~~~~~~~~~~~~~~~~~~~~~~~~~~~~~~~~~~~~~~~~~^^
  File "E:\Program Files\Python313\Lib\site-packages\jupyter_core\utils\__init__.py", line 165, in wrapped
    return loop.run_until_complete(inner)
           ~~~~~~~~~~~~~~~~~~~~~~~^^^^^^^
  File "E:\Program Files\Python313\Lib\asyncio\base_events.py", line 721, in run_until_complete
    return future.result()
           ~~~~~~~~~~~~~^^
  File "E:\Program Files\Python313\Lib\site-packages\nbclient\client.py", line 709, in async_execute
    await self.async_execute_cell(
        cell, index, execution_count=self.code_cells_executed + 1
    )
  File "E:\Program Files\Python313\Lib\site-packages\nbclient\client.py", line 1062, in async_execute_cell
    await self._check_raise_for_error(cell, cell_index, exec_reply)
  File "E:\Program Files\Python313\Lib\site-packages\nbclient\client.py", line 918, in _check_raise_for_error
    raise CellExecutionError.from_cell_and_msg(cell, exec_reply_content)
nbclient.exceptions.CellExecutionError: An error occurred while executing the following cell:
------------------
import numpy as np

# ÂéüÂßãÊï∞ÊçÆ
data = np.array([[1, 2], [3, 4], [5, 6]])

# Ê≠•È™§ 1: Êï∞ÊçÆÊ†áÂáÜÂåñ
mean = np.mean(data, axis=0)
std_dev = np.std(data, axis=0)
data_normalized = (data - mean) / std_dev

# Ê≠•È™§ 2: ËÆ°ÁÆóÂçèÊñπÂ∑ÆÁü©Èòµ
cov_matrix = np.cov(data_normalized, rowvar=False)

# Ê≠•È™§ 3: ËÆ°ÁÆóÁâπÂæÅÂÄºÂíåÁâπÂæÅÂêëÈáè
eigenvalues, eigenvectors = np.linalg.eig(cov_matrix)

# Ê≠•È™§ 4: ÈÄâÊã©‰∏ªÊàêÂàÜÔºàÊúÄÂ§ßÁâπÂæÅÂÄºÂØπÂ∫îÁöÑÁâπÂæÅÂêëÈáèÔºâ
sorted_indexes = np.argsort(eigenvalues)[::-1]
principal_components = eigenvectors[:, sorted_indexes[:1]]

# Ê≠•È™§ 5: ËΩ¨Êç¢Âà∞Êñ∞Á©∫Èó¥
transformed_data = np.dot(data_normalized, principal_components)

print("ÂéüÂßãÊï∞ÊçÆÔºö\n", data)
------------------


[1;31m---------------------------------------------------------------------------[0m
[1;31mModuleNotFoundError[0m                       Traceback (most recent call last)
Cell [1;32mIn[1], line 1[0m
[1;32m----> 1[0m [38;5;28;01mimport[39;00m [38;5;21;01mnumpy[39;00m [38;5;28;01mas[39;00m [38;5;21;01mnp[39;00m
[0;32m      3[0m [38;5;66;03m# ÂéüÂßãÊï∞ÊçÆ[39;00m
[0;32m      4[0m data [38;5;241m=[39m np[38;5;241m.[39marray([[[38;5;241m1[39m, [38;5;241m2[39m], [[38;5;241m3[39m, [38;5;241m4[39m], [[38;5;241m5[39m, [38;5;241m6[39m]])

[1;31mModuleNotFoundError[0m: No module named 'numpy'

