Traceback (most recent call last):
  File "E:\Tools\Python\3_12_6\Lib\site-packages\jupyter_cache\executors\utils.py", line 58, in single_nb_execution
    executenb(
  File "E:\Tools\Python\3_12_6\Lib\site-packages\nbclient\client.py", line 1314, in execute
    return NotebookClient(nb=nb, resources=resources, km=km, **kwargs).execute()
           ^^^^^^^^^^^^^^^^^^^^^^^^^^^^^^^^^^^^^^^^^^^^^^^^^^^^^^^^^^^^^^^^^^^^^
  File "E:\Tools\Python\3_12_6\Lib\site-packages\jupyter_core\utils\__init__.py", line 165, in wrapped
    return loop.run_until_complete(inner)
           ^^^^^^^^^^^^^^^^^^^^^^^^^^^^^^
  File "E:\Tools\Python\3_12_6\Lib\asyncio\base_events.py", line 687, in run_until_complete
    return future.result()
           ^^^^^^^^^^^^^^^
  File "E:\Tools\Python\3_12_6\Lib\site-packages\nbclient\client.py", line 709, in async_execute
    await self.async_execute_cell(
  File "E:\Tools\Python\3_12_6\Lib\site-packages\nbclient\client.py", line 1062, in async_execute_cell
    await self._check_raise_for_error(cell, cell_index, exec_reply)
  File "E:\Tools\Python\3_12_6\Lib\site-packages\nbclient\client.py", line 918, in _check_raise_for_error
    raise CellExecutionError.from_cell_and_msg(cell, exec_reply_content)
nbclient.exceptions.CellExecutionError: An error occurred while executing the following cell:
------------------
from sklearn.datasets import load_iris
from sklearn.model_selection import train_test_split
from sklearn.linear_model import LogisticRegression
from sklearn.preprocessing import StandardScaler
from sklearn.metrics import accuracy_score

# 加载鸢尾花数据集
iris = load_iris()
X, y = iris.data, iris.target

# 数据标准化
scaler = StandardScaler()
X_scaled = scaler.fit_transform(X)

# 划分数据集为训练集和测试集
X_train, X_test, y_train, y_test = train_test_split(X_scaled, y, test_size=0.2, random_state=42)

# 创建逻辑回归模型，并设置正则化参数C（C的倒数表示正则化强度，即较小的C值表示较强的正则化）
log_reg = LogisticRegression(C=1.0, penalty='l2', solver='liblinear')

# 在训练集上拟合模型
log_reg.fit(X_train, y_train)

# 在测试集上进行预测
y_pred = log_reg.predict(X_test)

# 计算模型准确率
accuracy = accuracy_score(y_test, y_pred)
print("模型准确率：", accuracy)

------------------


[1;31m---------------------------------------------------------------------------[0m
[1;31mModuleNotFoundError[0m                       Traceback (most recent call last)
Cell [1;32mIn[1], line 1[0m
[1;32m----> 1[0m [38;5;28;01mfrom[39;00m [38;5;21;01msklearn[39;00m[38;5;21;01m.[39;00m[38;5;21;01mdatasets[39;00m [38;5;28;01mimport[39;00m load_iris
[0;32m      2[0m [38;5;28;01mfrom[39;00m [38;5;21;01msklearn[39;00m[38;5;21;01m.[39;00m[38;5;21;01mmodel_selection[39;00m [38;5;28;01mimport[39;00m train_test_split
[0;32m      3[0m [38;5;28;01mfrom[39;00m [38;5;21;01msklearn[39;00m[38;5;21;01m.[39;00m[38;5;21;01mlinear_model[39;00m [38;5;28;01mimport[39;00m LogisticRegression

[1;31mModuleNotFoundError[0m: No module named 'sklearn'

